Workbook

Sheet LEIA-ME
A1: PPR Comex · Planilha de controle
A3: Colunas azuis: você (ou o agente) preenche. Colunas verdes: fórmulas, não editar.
A4: Comece pela aba Parametros: troque o Mês de referência todo mês (sempre dia 01).
A6: Meta 1 · Volume (75 t/mês): aba Pedidos (só lançar pedidos; o Painel calcula).
A7: Meta 2 · Positivação +20%: abas Clientes, Pedidos e Acompanhamento.
A8: Clientes: um por linha, com a periodicidade de compra (1, 2, 3, 4, 6 ou 12 meses).
A9: Pedidos: lançar os pedidos do ano base (2025) e do ano meta (2026).
A10: Acompanhamento: um registro por cliente que não recomprou no mês, com motivo e ação.
A11: Meta 3a · Gestão das S.A.: aba S_Atividades (uma linha por atividade solicitada).
A12: O prazo de cada setor vem da tabela de SLA da aba Parametros se a coluna Prazo ficar vazia.
A13: Registre cada cobrança feita (Nº cobranças e Última cobrança): é a prova da sua gestão.
A14: Meta 3b · Redução de custo: aba Custos (uma linha por ação; referência x realizado).
... A17: Relatório do mês: python3 ppr-comex/scripts/relatorio_mensal.py <planilha> --mes AAAA-MM

Sheet Painel
A1: Painel PPR Comex · mês de referência: | B1: =Parametros!$B$2
A2: META 1 · VOLUME
A3: Toneladas vendidas no mês | B3: =SUMIFS(Pedidos!$E:$E,Pedidos!$B:$B,">="&Parametros!$B$2,Pedidos!$B:$B,"<="&EOMONTH(Parametros!$B$2,0))
A4: Média mensal no ano (até o mês de referência) | B4: =SUMIFS(Pedidos!$E:$E,Pedidos!$K:$K,Parametros!$B$4,Pedidos!$B:$B,"<="&EOMONTH(Parametros!$B$2,0))/MONTH(Parametros!$B$2)
A5: Meta (t/mês) | B5: =Parametros!$B$6
A6: META 2 · POSITIVAÇÃO
A7: Clientes positivados no ano base | B7: =COUNTIF(Clientes!$I:$I,">0")
A8: Meta de clientes no ano (+20%) | B8: =ROUNDUP(B7*(1+Parametros!$B$5),0)
A9: Clientes positivados no ano meta (acumulado) | B9: =COUNTIF(Clientes!$K:$K,">0")
A10: Pedidos no ano base | B10: =COUNTIF(Pedidos!$K:$K,Parametros!$B$3)
A11: Meta de pedidos no ano (+20%) | B11: =ROUNDUP(B10*(1+Parametros!$B$5),0)
A12: Pedidos no ano meta (acumulado) | B12: =COUNTIF(Pedidos!$K:$K,Parametros!$B$4)
A13: Clientes que compraram no mês | B13: =COUNTIF(Clientes!$N:$N,"Comprou no mês")
A14: Clientes previstos no mês e ainda sem pedido | B14: =COUNTIF(Clientes!$N:$N,"Previsto no mês")
A15: Clientes atrasados na recompra | B15: =COUNTIF(Clientes!$N:$N,"Atrasado")
A16: Motivos registrados no mês | B16: =COUNTIFS(Acompanhamento!$A:$A,Parametros!$B$2)
A17: META 3a · S.A. E PRAZO DE EMBARQUE
A18: Atividades concluídas no mês | B18: =COUNTIFS(S_Atividades!$G:$G,">="&Parametros!$B$2,S_Atividades!$G:$G,"<="&EOMONTH(Parametros!$B$2,0))
A19: % concluídas no prazo | B19: =IFERROR(COUNTIFS(S_Atividades!$G:$G,">="&Parametros!$B$2,S_Atividades!$G:$G,"<="&EOMONTH(Parametros!$B$2,0),S_Atividades!$M:$M,"No prazo")/B18,"")
A20: Atividades em aberto atrasadas (hoje) | B20: =COUNTIF(S_Atividades!$M:$M,"Atrasada")
A21: Cobranças feitas (atividades do mês) | B21: =SUMIFS(S_Atividades!$H:$H,S_Atividades!$E:$E,">="&Parametros!$B$2,S_Atividades!$E:$E,"<="&EOMONTH(Parametros!$B$2,0))
A22: Pedidos embarcados no mês | B22: =COUNTIFS(Pedidos!$I:$I,">="&Parametros!$B$2,Pedidos!$I:$I,"<="&EOMONTH(Parametros!$B$2,0))
A23: % embarcados no prazo negociado | B23: =IFERROR(COUNTIFS(Pedidos!$I:$I,">="&Parametros!$B$2,Pedidos!$I:$I,"<="&EOMONTH(Parametros!$B$2,0),Pedidos!$N:$N,"No prazo")/B22,"")
A24: META 3b · REDUÇÃO DE CUSTO
A25: Economia registrada no mês (R$) | B25: =SUMIFS(Custos!$I:$I,Custos!$A:$A,Parametros!$B$2)
A26: Economia acumulada no ano (R$) | B26: =SUMIFS(Custos!$I:$I,Custos!$A:$A,">="&DATE(Parametros!$B$4,1,1),Custos!$A:$A,"<="&EOMONTH(Parametros!$B$2,0))
A27: META 3c · GIRO DE EMBALAGENS
A28: Valor parado em embalagens obsoletas (R$) | B28: =SUMIFS(Embalagens!$O:$O,Embalagens!$L:$L,"Obsoleta")
A29: Valor reaproveitado no mês (R$) | B29: =SUMIFS(Uso_Embalagens!$J:$J,Uso_Embalagens!$A:$A,">="&Parametros!$B$2,Uso_Embalagens!$A:$A,"<="&EOMONTH(Parametros!$B$2,0))
A30: Unidades reaproveitadas no mês | B30: =SUMIFS(Uso_Embalagens!$E:$E,Uso_Embalagens!$A:$A,">="&Parametros!$B$2,Uso_Embalagens!$A:$A,"<="&EOMONTH(Parametros!$B$2,0))

Sheet Parametros
A1: Parâmetro | B1: Valor | C1: Observação | E1: Departamento | F1: Prazo padrão (dias)
A2: Mês de referência | B2: 46266 | C2: Primeiro dia do mês que está sendo apurado | E2: Comercial/Comex | F2: 2
A3: Ano base | B3: 2025 | C3: Ano usado como base da positivação | E3: Compras/Suprimentos | F3: 10
A4: Ano meta | B4: 2026 | C4: Ano do PPR | E4: Marketing/Arte | F4: 7
A5: Meta de aumento de positivação | B5: 0.2 | C5: 20% sobre o ano base | E5: Qualidade/Regulatório | F5: 7
A6: Meta de volume (t/mês) | B6: 75 | C6: Média mensal | E6: PCP/Produção | F6: 15
A7: Prazo de embarque padrão (dias) | B7: 30 | C7: Prazo negociado com o cliente | E7: Logística/Embarque | F7: 5
A8: Idade para obsoleta (meses) | B8: 12 | C8: Embalagem parada há mais tempo que isso | E8: Financeiro | F8: 3
E9: Documentação/Despachante | F9: 5

Sheet Clientes
A1: Cód. Cliente | B1: Cliente | C1: País | D1: Idioma | E1: Canal/Representante | F1: Periodicidade (meses) | G1: Status cadastro | H1: Observação | I1: Pedidos ano base | J1: Toneladas ano base | K1: Pedidos ano meta | L1: Último pedido | M1: Próxima compra prevista | N1: Situação no mês
A2: C001 | B2: Cliente Exemplo 01 | C2: Estados Unidos | D2: Inglês | E2: Agente LatAm | F2: 2 | G2: Ativo | I2: =IF(A2="","",COUNTIFS(Pedidos!$C:$C,A2,Pedidos!$K:$K,Parametros!$B$3)) | J2: =IF(A2="","",SUMIFS(Pedidos!$E:$E,Pedidos!$C:$C,A2,Pedidos!$K:$K,Parametros!$B$3)) | K2: =IF(A2="","",COUNTIFS(Pedidos!$C:$C,A2,Pedidos!$K:$K,Parametros!$B$4)) | L2: =IF(A2="","",IF(COUNTIFS(Pedidos!$C:$C,A2,Pedidos!$B:$B,"<="&EOMONTH(Parametros!$B$2,0))=0,"",_xlfn.MAXIFS(Pedidos!$B:$B,Pedidos!$C:$C,A2,Pedidos!$B:$B,"<="&EOMONTH(Parametros!$B$2,0)))) | M2: =IF(OR(L2="",F2=""),"",EDATE(L2,F2)) | N2: =IF(A2="","",IF(L2="","Sem histórico",IF(AND(L2>=Parametros!$B$2,L2<=EOMONTH(Parametros!$B$2,0)),"Comprou no mês",IF(M2="","Sem periodicidade",IF(M2<Parametros!$B$2,"Atrasado",IF(M2<=EOMONTH(Parametros!$B$2,0),"Previsto no mês","Em dia"))))))
A3: C002 | B3: Cliente Exemplo 02 | C3: Paraguai | D3: Espanhol | E3: Trading | F3: 1 | G3: Ativo | I3: =IF(A3="","",COUNTIFS(Pedidos!$C:$C,A3,Pedidos!$K:$K,Parametros!$B$3)) | J3: =IF(A3="","",SUMIFS(Pedidos!$E:$E,Pedidos!$C:$C,A3,Pedidos!$K:$K,Parametros!$B$3)) | K3: =IF(A3="","",COUNTIFS(Pedidos!$C:$C,A3,Pedidos!$K:$K,Parametros!$B$4)) | L3: =IF(A3="","",IF(COUNTIFS(Pedidos!$C:$C,A3,Pedidos!$B:$B,"<="&EOMONTH(Parametros!$B$2,0))=0,"",_xlfn.MAXIFS(Pedidos!$B:$B,Pedidos!$C:$C,A3,Pedidos!$B:$B,"<="&EOMONTH(Parametros!$B$2,0)))) | M3: =IF(OR(L3="",F3=""),"",EDATE(L3,F3)) | N3: =IF(A3="","",IF(L3="","Sem histórico",IF(AND(L3>=Parametros!$B$2,L3<=EOMONTH(Parametros!$B$2,0)),"Comprou no mês",IF(M3="","Sem periodicidade",IF(M3<Parametros!$B$2,"Atrasado",IF(M3<=EOMONTH(Parametros!$B$2,0),"Previsto no mês","Em dia"))))))
A4: C003 | B4: Cliente Exemplo 03 | C4: Chile | D4: Espanhol | E4: Trading | F4: 2 | G4: Ativo | I4: =IF(A4="","",COUNTIFS(Pedidos!$C:$C,A4,Pedidos!$K:$K,Parametros!$B$3)) | J4: =IF(A4="","",SUMIFS(Pedidos!$E:$E,Pedidos!$C:$C,A4,Pedidos!$K:$K,Parametros!$B$3)) | K4: =IF(A4="","",COUNTIFS(Pedidos!$C:$C,A4,Pedidos!$K:$K,Parametros!$B$4)) | L4: =IF(A4="","",IF(COUNTIFS(Pedidos!$C:$C,A4,Pedidos!$B:$B,"<="&EOMONTH(Parametros!$B$2,0))=0,"",_xlfn.MAXIFS(Pedidos!$B:$B,Pedidos!$C:$C,A4,Pedidos!$B:$B,"<="&EOMONTH(Parametros!$B$2,0)))) | M4: =IF(OR(L4="",F4=""),"",EDATE(L4,F4)) | N4: =IF(A4="","",IF(L4="","Sem histórico",IF(AND(L4>=Parametros!$B$2,L4<=EOMONTH(Parametros!$B$2,0)),"Comprou no mês",IF(M4="","Sem periodicidade",IF(M4<Parametros!$B$2,"Atrasado",IF(M4<=EOMONTH(Parametros!$B$2,0),"Previsto no mês","Em dia"))))))
A5: C004 | B5: Cliente Exemplo 04 | C5: Paraguai | D5: Espanhol | E5: Direto | F5: 3 | G5: Ativo | I5: =IF(A5="","",COUNTIFS(Pedidos!$C:$C,A5,Pedidos!$K:$K,Parametros!$B$3)) | J5: =IF(A5="","",SUMIFS(Pedidos!$E:$E,Pedidos!$C:$C,A5,Pedidos!$K:$K,Parametros!$B$3)) | K5: =IF(A5="","",COUNTIFS(Pedidos!$C:$C,A5,Pedidos!$K:$K,Parametros!$B$4)) | L5: =IF(A5="","",IF(COUNTIFS(Pedidos!$C:$C,A5,Pedidos!$B:$B,"<="&EOMONTH(Parametros!$B$2,0))=0,"",_xlfn.MAXIFS(Pedidos!$B:$B,Pedidos!$C:$C,A5,Pedidos!$B:$B,"<="&EOMONTH(Parametros!$B$2,0)))) | M5: =IF(OR(L5="",F5=""),"",EDATE(L5,F5)) | N5: =IF(A5="","",IF(L5="","Sem histórico",IF(AND(L5>=Parametros!$B$2,L5<=EOMONTH(Parametros!$B$2,0)),"Comprou no mês",IF(M5="","Sem periodicidade",IF(M5<Parametros!$B$2,"Atrasado",IF(M5<=EOMONTH(Parametros!$B$2,0),"Previsto no mês","Em dia"))))))
A6: C005 | B6: Cliente Exemplo 05 | C6: Paraguai | D6: Espanhol | E6: Agente LatAm | F6: 1 | G6: Ativo | I6: =IF(A6="","",COUNTIFS(Pedidos!$C:$C,A6,Pedidos!$K:$K,Parametros!$B$3)) | J6: =IF(A6="","",SUMIFS(Pedidos!$E:$E,Pedidos!$C:$C,A6,Pedidos!$K:$K,Parametros!$B$3)) | K6: =IF(A6="","",COUNTIFS(Pedidos!$C:$C,A6,Pedidos!$K:$K,Parametros!$B$4)) | L6: =IF(A6="","",IF(COUNTIFS(Pedidos!$C:$C,A6,Pedidos!$B:$B,"<="&EOMONTH(Parametros!$B$2,0))=0,"",_xlfn.MAXIFS(Pedidos!$B:$B,Pedidos!$C:$C,A6,Pedidos!$B:$B,"<="&EOMONTH(Parametros!$B$2,0)))) | M6: =IF(OR(L6="",F6=""),"",EDATE(L6,F6)) | N6: =IF(A6="","",IF(L6="","Sem histórico",IF(AND(L6>=Parametros!$B$2,L6<=EOMONTH(Parametros!$B$2,0)),"Comprou no mês",IF(M6="","Sem periodicidade",IF(M6<Parametros!$B$2,"Atrasado",IF(M6<=EOMONTH(Parametros!$B$2,0),"Previsto no mês","Em dia"))))))
A7: C006 | B7: Cliente Exemplo 06 | C7: Japão | D7: Japonês | E7: Direto | F7: 1 | G7: Ativo | I7: =IF(A7="","",COUNTIFS(Pedidos!$C:$C,A7,Pedidos!$K:$K,Parametros!$B$3)) | J7: =IF(A7="","",SUMIFS(Pedidos!$E:$E,Pedidos!$C:$C,A7,Pedidos!$K:$K,Parametros!$B$3)) | K7: =IF(A7="","",COUNTIFS(Pedidos!$C:$C,A7,Pedidos!$K:$K,Parametros!$B$4)) | L7: =IF(A7="","",IF(COUNTIFS(Pedidos!$C:$C,A7,Pedidos!$B:$B,"<="&EOMONTH(Parametros!$B$2,0))=0,"",_xlfn.MAXIFS(Pedidos!$B:$B,Pedidos!$C:$C,A7,Pedidos!$B:$B,"<="&EOMONTH(Parametros!$B$2,0)))) | M7: =IF(OR(L7="",F7=""),"",EDATE(L7,F7)) | N7: =IF(A7="","",IF(L7="","Sem histórico",IF(AND(L7>=Parametros!$B$2,L7<=EOMONTH(Parametros!$B$2,0)),"Comprou no mês",IF(M7="","Sem periodicidade",IF(M7<Parametros!$B$2,"Atrasado",IF(M7<=EOMONTH(Parametros!$B$2,0),"Previsto no mês","Em dia"))))))
A8: C007 | B8: Cliente Exemplo 07 | C8: Chile | D8: Espanhol | E8: Agente LatAm | F8: 3 | G8: Ativo | I8: =IF(A8="","",COUNTIFS(Pedidos!$C:$C,A8,Pedidos!$K:$K,Parametros!$B$3)) | J8: =IF(A8="","",SUMIFS(Pedidos!$E:$E,Pedidos!$C:$C,A8,Pedidos!$K:$K,Parametros!$B$3)) | K8: =IF(A8="","",COUNTIFS(Pedidos!$C:$C,A8,Pedidos!$K:$K,Parametros!$B$4)) | L8: =IF(A8="","",IF(COUNTIFS(Pedidos!$C:$C,A8,Pedidos!$B:$B,"<="&EOMONTH(Parametros!$B$2,0))=0,"",_xlfn.MAXIFS(Pedidos!$B:$B,Pedidos!$C:$C,A8,Pedidos!$B:$B,"<="&EOMONTH(Parametros!$B$2,0)))) | M8: =IF(OR(L8="",F8=""),"",EDATE(L8,F8)) | N8: =IF(A8="","",IF(L8="","Sem histórico",IF(AND(L8>=Parametros!$B$2,L8<=EOMONTH(Parametros!$B$2,0)),"Comprou no mês",IF(M8="","Sem periodicidade",IF(M8<Parametros!$B$2,"Atrasado",IF(M8<=EOMONTH(Parametros!$B$2,0),"Previsto no mês","Em dia"))))))
A9: C008 | B9: Cliente Exemplo 08 | C9: Paraguai | D9: Espanhol | E9: Trading | F9: 6 | G9: Ativo | I9: =IF(A9="","",COUNTIFS(Pedidos!$C:$C,A9,Pedidos!$K:$K,Parametros!$B$3)) | J9: =IF(A9="","",SUMIFS(Pedidos!$E:$E,Pedidos!$C:$C,A9,Pedidos!$K:$K,Parametros!$B$3)) | K9: =IF(A9="","",COUNTIFS(Pedidos!$C:$C,A9,Pedidos!$K:$K,Parametros!$B$4)) | L9: =IF(A9="","",IF(COUNTIFS(Pedidos!$C:$C,A9,Pedidos!$B:$B,"<="&EOMONTH(Parametros!$B$2,0))=0,"",_xlfn.MAXIFS(Pedidos!$B:$B,Pedidos!$C:$C,A9,Pedidos!$B:$B,"<="&EOMONTH(Parametros!$B$2,0)))) | M9: =IF(OR(L9="",F9=""),"",EDATE(L9,F9)) | N9: =IF(A9="","",IF(L9="","Sem histórico",IF(AND(L9>=Parametros!$B$2,L9<=EOMONTH(Parametros!$B$2,0)),"Comprou no mês",IF(M9="","Sem periodicidade",IF(M9<Parametros!$B$2,"Atrasado",IF(M9<=EOMONTH(Parametros!$B$2,0),"Previsto no mês","Em dia"))))))
A10: C009 | B10: Cliente Exemplo 09 | C10: Chile | D10: Espanhol | E10: Trading | F10: 2 | G10: Ativo | I10: =IF(A10="","",COUNTIFS(Pedidos!$C:$C,A10,Pedidos!$K:$K,Parametros!$B$3)) | J10: =IF(A10="","",SUMIFS(Pedidos!$E:$E,Pedidos!$C:$C,A10,Pedidos!$K:$K,Parametros!$B$3)) | K10: =IF(A10="","",COUNTIFS(Pedidos!$C:$C,A10,Pedidos!$K:$K,Parametros!$B$4)) | L10: =IF(A10="","",IF(COUNTIFS(Pedidos!$C:$C,A10,Pedidos!$B:$B,"<="&EOMONTH(Parametros!$B$2,0))=0,"",_xlfn.MAXIFS(Pedidos!$B:$B,Pedidos!$C:$C,A10,Pedidos!$B:$B,"<="&EOMONTH(Parametros!$B$2,0)))) | M10: =IF(OR(L10="",F10=""),"",EDATE(L10,F10)) | N10: =IF(A10="","",IF(L10="","Sem histórico",IF(AND(L10>=Parametros!$B$2,L10<=EOMONTH(Parametros!$B$2,0)),"Comprou no mês",IF(M10="","Sem periodicidade",IF(M10<Parametros!$B$2,"Atrasado",IF(M10<=EOMONTH(Parametros!$B$2,0),"Previsto no mês","Em dia"))))))
A11: C010 | B11: Cliente Exemplo 10 | C11: Gana | D11: Inglês | E11: Trading | F11: 1 | G11: Ativo | I11: =IF(A11="","",COUNTIFS(Pedidos!$C:$C,A11,Pedidos!$K:$K,Parametros!$B$3)) | J11: =IF(A11="","",SUMIFS(Pedidos!$E:$E,Pedidos!$C:$C,A11,Pedidos!$K:$K,Parametros!$B$3)) | K11: =IF(A11="","",COUNTIFS(Pedidos!$C:$C,A11,Pedidos!$K:$K,Parametros!$B$4)) | L11: =IF(A11="","",IF(COUNTIFS(Pedidos!$C:$C,A11,Pedidos!$B:$B,"<="&EOMONTH(Parametros!$B$2,0))=0,"",_xlfn.MAXIFS(Pedidos!$B:$B,Pedidos!$C:$C,A11,Pedidos!$B:$B,"<="&EOMONTH(Parametros!$B$2,0)))) | M11: =IF(OR(L11="",F11=""),"",EDATE(L11,F11)) | N11: =IF(A11="","",IF(L11="","Sem histórico",IF(AND(L11>=Parametros!$B$2,L11<=EOMONTH(Parametros!$B$2,0)),"Comprou no mês",IF(M11="","Sem periodicidade",IF(M11<Parametros!$B$2,"Atrasado",IF(M11<=EOMONTH(Parametros!$B$2,0),"Previsto no mês","Em dia"))))))
A12: C011 | B12: Cliente Exemplo 11 | C12: Gana | D12: Inglês | E12: Direto | F12: 3 | G12: Ativo | I12: =IF(A12="","",COUNTIFS(Pedidos!$C:$C,A12,Pedidos!$K:$K,Parametros!$B$3)) | J12: =IF(A12="","",SUMIFS(Pedidos!$E:$E,Pedidos!$C:$C,A12,Pedidos!$K:$K,Parametros!$B$3)) | K12: =IF(A12="","",COUNTIFS(Pedidos!$C:$C,A12,Pedidos!$K:$K,Parametros!$B$4)) | L12: =IF(A12="","",IF(COUNTIFS(Pedidos!$C:$C,A12,Pedidos!$B:$B,"<="&EOMONTH(Parametros!$B$2,0))=0,"",_xlfn.MAXIFS(Pedidos!$B:$B,Pedidos!$C:$C,A12,Pedidos!$B:$B,"<="&EOMONTH(Parametros!$B$2,0)))) | M12: =IF(OR(L12="",F12=""),"",EDATE(L12,F12)) | N12: =IF(A12="","",IF(L12="","Sem histórico",IF(AND(L12>=Parametros!$B$2,L12<=EOMONTH(Parametros!$B$2,0)),"Comprou no mês",IF(M12="","Sem periodicidade",IF(M12<Parametros!$B$2,"Atrasado",IF(M12<=EOMONTH(Parametros!$B$2,0),"Previsto no mês","Em dia"))))))
A13: C012 | B13: Cliente Exemplo 12 | C13: Angola | D13: Português | E13: Trading | F13: 1 | G13: Ativo | I13: =IF(A13="","",COUNTIFS(Pedidos!$C:$C,A13,Pedidos!$K:$K,Parametros!$B$3)) | J13: =IF(A13="","",SUMIFS(Pedidos!$E:$E,Pedidos!$C:$C,A13,Pedidos!$K:$K,Parametros!$B$3)) | K13: =IF(A13="","",COUNTIFS(Pedidos!$C:$C,A13,Pedidos!$K:$K,Parametros!$B$4)) | L13: =IF(A13="","",IF(COUNTIFS(Pedidos!$C:$C,A13,Pedidos!$B:$B,"<="&EOMONTH(Parametros!$B$2,0))=0,"",_xlfn.MAXIFS(Pedidos!$B:$B,Pedidos!$C:$C,A13,Pedidos!$B:$B,"<="&EOMONTH(Parametros!$B$2,0)))) | M13: =IF(OR(L13="",F13=""),"",EDATE(L13,F13)) | N13: =IF(A13="","",IF(L13="","Sem histórico",IF(AND(L13>=Parametros!$B$2,L13<=EOMONTH(Parametros!$B$2,0)),"Comprou no mês",IF(M13="","Sem periodicidade",IF(M13<Parametros!$B$2,"Atrasado",IF(M13<=EOMONTH(Parametros!$B$2,0),"Previsto no mês","Em dia"))))))
... A27: C026 | B27: Cliente Exemplo 26 | C27: Peru | D27: Espanhol | E27: Agente LatAm | F27: 3 | G27: Ativo | I27: =IF(A27="","",COUNTIFS(Pedidos!$C:$C,A27,Pedidos!$K:$K,Parametros!$B$3)) | J27: =IF(A27="","",SUMIFS(Pedidos!$E:$E,Pedidos!$C:$C,A27,Pedidos!$K:$K,Parametros!$B$3)) | K27: =IF(A27="","",COUNTIFS(Pedidos!$C:$C,A27,Pedidos!$K:$K,Parametros!$B$4)) | L27: =IF(A27="","",IF(COUNTIFS(Pedidos!$C:$C,A27,Pedidos!$B:$B,"<="&EOMONTH(Parametros!$B$2,0))=0,"",_xlfn.MAXIFS(Pedidos!$B:$B,Pedidos!$C:$C,A27,Pedidos!$B:$B,"<="&EOMONTH(Parametros!$B$2,0)))) | M27: =IF(OR(L27="",F27=""),"",EDATE(L27,F27)) | N27: =IF(A27="","",IF(L27="","Sem histórico",IF(AND(L27>=Parametros!$B$2,L27<=EOMONTH(Parametros!$B$2,0)),"Comprou no mês",IF(M27="","Sem periodicidade",IF(M27<Parametros!$B$2,"Atrasado",IF(M27<=EOMONTH(Parametros!$B$2,0),"Previsto no mês","Em dia"))))))
I28: =IF(A28="","",COUNTIFS(Pedidos!$C:$C,A28,Pedidos!$K:$K,Parametros!$B$3)) | J28: =IF(A28="","",SUMIFS(Pedidos!$E:$E,Pedidos!$C:$C,A28,Pedidos!$K:$K,Parametros!$B$3)) | K28: =IF(A28="","",COUNTIFS(Pedidos!$C:$C,A28,Pedidos!$K:$K,Parametros!$B$4)) | L28: =IF(A28="","",IF(COUNTIFS(Pedidos!$C:$C,A28,Pedidos!$B:$B,"<="&EOMONTH(Parametros!$B$2,0))=0,"",_xlfn.MAXIFS(Pedidos!$B:$B,Pedidos!$C:$C,A28,Pedidos!$B:$B,"<="&EOMONTH(Parametros!$B$2,0)))) | M28: =IF(OR(L28="",F28=""),"",EDATE(L28,F28)) | N28: =IF(A28="","",IF(L28="","Sem histórico",IF(AND(L28>=Parametros!$B$2,L28<=EOMONTH(Parametros!$B$2,0)),"Comprou no mês",IF(M28="","Sem periodicidade",IF(M28<Parametros!$B$2,"Atrasado",IF(M28<=EOMONTH(Parametros!$B$2,0),"Previsto no mês","Em dia"))))))
I29: =IF(A29="","",COUNTIFS(Pedidos!$C:$C,A29,Pedidos!$K:$K,Parametros!$B$3)) | J29: =IF(A29="","",SUMIFS(Pedidos!$E:$E,Pedidos!$C:$C,A29,Pedidos!$K:$K,Parametros!$B$3)) | K29: =IF(A29="","",COUNTIFS(Pedidos!$C:$C,A29,Pedidos!$K:$K,Parametros!$B$4)) | L29: =IF(A29="","",IF(COUNTIFS(Pedidos!$C:$C,A29,Pedidos!$B:$B,"<="&EOMONTH(Parametros!$B$2,0))=0,"",_xlfn.MAXIFS(Pedidos!$B:$B,Pedidos!$C:$C,A29,Pedidos!$B:$B,"<="&EOMONTH(Parametros!$B$2,0)))) | M29: =IF(OR(L29="",F29=""),"",EDATE(L29,F29)) | N29: =IF(A29="","",IF(L29="","Sem histórico",IF(AND(L29>=Parametros!$B$2,L29<=EOMONTH(Parametros!$B$2,0)),"Comprou no mês",IF(M29="","Sem periodicidade",IF(M29<Parametros!$B$2,"Atrasado",IF(M29<=EOMONTH(Parametros!$B$2,0),"Previsto no mês","Em dia"))))))
I30: =IF(A30="","",COUNTIFS(Pedidos!$C:$C,A30,Pedidos!$K:$K,Parametros!$B$3)) | J30: =IF(A30="","",SUMIFS(Pedidos!$E:$E,Pedidos!$C:$C,A30,Pedidos!$K:$K,Parametros!$B$3)) | K30: =IF(A30="","",COUNTIFS(Pedidos!$C:$C,A30,Pedidos!$K:$K,Parametros!$B$4)) | L30: =IF(A30="","",IF(COUNTIFS(Pedidos!$C:$C,A30,Pedidos!$B:$B,"<="&EOMONTH(Parametros!$B$2,0))=0,"",_xlfn.MAXIFS(Pedidos!$B:$B,Pedidos!$C:$C,A30,Pedidos!$B:$B,"<="&EOMONTH(Parametros!$B$2,0)))) | M30: =IF(OR(L30="",F30=""),"",EDATE(L30,F30)) | N30: =IF(A30="","",IF(L30="","Sem histórico",IF(AND(L30>=Parametros!$B$2,L30<=EOMONTH(Parametros!$B$2,0)),"Comprou no mês",IF(M30="","Sem periodicidade",IF(M30<Parametros!$B$2,"Atrasado",IF(M30<=EOMONTH(Parametros!$B$2,0),"Previsto no mês","Em dia"))))))
I31: =IF(A31="","",COUNTIFS(Pedidos!$C:$C,A31,Pedidos!$K:$K,Parametros!$B$3)) | J31: =IF(A31="","",SUMIFS(Pedidos!$E:$E,Pedidos!$C:$C,A31,Pedidos!$K:$K,Parametros!$B$3)) | K31: =IF(A31="","",COUNTIFS(Pedidos!$C:$C,A31,Pedidos!$K:$K,Parametros!$B$4)) | L31: =IF(A31="","",IF(COUNTIFS(Pedidos!$C:$C,A31,Pedidos!$B:$B,"<="&EOMONTH(Parametros!$B$2,0))=0,"",_xlfn.MAXIFS(Pedidos!$B:$B,Pedidos!$C:$C,A31,Pedidos!$B:$B,"<="&EOMONTH(Parametros!$B$2,0)))) | M31: =IF(OR(L31="",F31=""),"",EDATE(L31,F31)) | N31: =IF(A31="","",IF(L31="","Sem histórico",IF(AND(L31>=Parametros!$B$2,L31<=EOMONTH(Parametros!$B$2,0)),"Comprou no mês",IF(M31="","Sem periodicidade",IF(M31<Parametros!$B$2,"Atrasado",IF(M31<=EOMONTH(Parametros!$B$2,0),"Previsto no mês","Em dia"))))))
I32: =IF(A32="","",COUNTIFS(Pedidos!$C:$C,A32,Pedidos!$K:$K,Parametros!$B$3)) | J32: =IF(A32="","",SUMIFS(Pedidos!$E:$E,Pedidos!$C:$C,A32,Pedidos!$K:$K,Parametros!$B$3)) | K32: =IF(A32="","",COUNTIFS(Pedidos!$C:$C,A32,Pedidos!$K:$K,Parametros!$B$4)) | L32: =IF(A32="","",IF(COUNTIFS(Pedidos!$C:$C,A32,Pedidos!$B:$B,"<="&EOMONTH(Parametros!$B$2,0))=0,"",_xlfn.MAXIFS(Pedidos!$B:$B,Pedidos!$C:$C,A32,Pedidos!$B:$B,"<="&EOMONTH(Parametros!$B$2,0)))) | M32: =IF(OR(L32="",F32=""),"",EDATE(L32,F32)) | N32: =IF(A32="","",IF(L32="","Sem histórico",IF(AND(L32>=Parametros!$B$2,L32<=EOMONTH(Parametros!$B$2,0)),"Comprou no mês",IF(M32="","Sem periodicidade",IF(M32<Parametros!$B$2,"Atrasado",IF(M32<=EOMONTH(Parametros!$B$2,0),"Previsto no mês","Em dia"))))))
I33: =IF(A33="","",COUNTIFS(Pedidos!$C:$C,A33,Pedidos!$K:$K,Parametros!$B$3)) | J33: =IF(A33="","",SUMIFS(Pedidos!$E:$E,Pedidos!$C:$C,A33,Pedidos!$K:$K,Parametros!$B$3)) | K33: =IF(A33="","",COUNTIFS(Pedidos!$C:$C,A33,Pedidos!$K:$K,Parametros!$B$4)) | L33: =IF(A33="","",IF(COUNTIFS(Pedidos!$C:$C,A33,Pedidos!$B:$B,"<="&EOMONTH(Parametros!$B$2,0))=0,"",_xlfn.MAXIFS(Pedidos!$B:$B,Pedidos!$C:$C,A33,Pedidos!$B:$B,"<="&EOMONTH(Parametros!$B$2,0)))) | M33: =IF(OR(L33="",F33=""),"",EDATE(L33,F33)) | N33: =IF(A33="","",IF(L33="","Sem histórico",IF(AND(L33>=Parametros!$B$2,L33<=EOMONTH(Parametros!$B$2,0)),"Comprou no mês",IF(M33="","Sem periodicidade",IF(M33<Parametros!$B$2,"Atrasado",IF(M33<=EOMONTH(Parametros!$B$2,0),"Previsto no mês","Em dia"))))))
I34: =IF(A34="","",COUNTIFS(Pedidos!$C:$C,A34,Pedidos!$K:$K,Parametros!$B$3)) | J34: =IF(A34="","",SUMIFS(Pedidos!$E:$E,Pedidos!$C:$C,A34,Pedidos!$K:$K,Parametros!$B$3)) | K34: =IF(A34="","",COUNTIFS(Pedidos!$C:$C,A34,Pedidos!$K:$K,Parametros!$B$4)) | L34: =IF(A34="","",IF(COUNTIFS(Pedidos!$C:$C,A34,Pedidos!$B:$B,"<="&EOMONTH(Parametros!$B$2,0))=0,"",_xlfn.MAXIFS(Pedidos!$B:$B,Pedidos!$C:$C,A34,Pedidos!$B:$B,"<="&EOMONTH(Parametros!$B$2,0)))) | M34: =IF(OR(L34="",F34=""),"",EDATE(L34,F34)) | N34: =IF(A34="","",IF(L34="","Sem histórico",IF(AND(L34>=Parametros!$B$2,L34<=EOMONTH(Parametros!$B$2,0)),"Comprou no mês",IF(M34="","Sem periodicidade",IF(M34<Parametros!$B$2,"Atrasado",IF(M34<=EOMONTH(Parametros!$B$2,0),"Previsto no mês","Em dia"))))))
I35: =IF(A35="","",COUNTIFS(Pedidos!$C:$C,A35,Pedidos!$K:$K,Parametros!$B$3)) | J35: =IF(A35="","",SUMIFS(Pedidos!$E:$E,Pedidos!$C:$C,A35,Pedidos!$K:$K,Parametros!$B$3)) | K35: =IF(A35="","",COUNTIFS(Pedidos!$C:$C,A35,Pedidos!$K:$K,Parametros!$B$4)) | L35: =IF(A35="","",IF(COUNTIFS(Pedidos!$C:$C,A35,Pedidos!$B:$B,"<="&EOMONTH(Parametros!$B$2,0))=0,"",_xlfn.MAXIFS(Pedidos!$B:$B,Pedidos!$C:$C,A35,Pedidos!$B:$B,"<="&EOMONTH(Parametros!$B$2,0)))) | M35: =IF(OR(L35="",F35=""),"",EDATE(L35,F35)) | N35: =IF(A35="","",IF(L35="","Sem histórico",IF(AND(L35>=Parametros!$B$2,L35<=EOMONTH(Parametros!$B$2,0)),"Comprou no mês",IF(M35="","Sem periodicidade",IF(M35<Parametros!$B$2,"Atrasado",IF(M35<=EOMONTH(Parametros!$B$2,0),"Previsto no mês","Em dia"))))))
I36: =IF(A36="","",COUNTIFS(Pedidos!$C:$C,A36,Pedidos!$K:$K,Parametros!$B$3)) | J36: =IF(A36="","",SUMIFS(Pedidos!$E:$E,Pedidos!$C:$C,A36,Pedidos!$K:$K,Parametros!$B$3)) | K36: =IF(A36="","",COUNTIFS(Pedidos!$C:$C,A36,Pedidos!$K:$K,Parametros!$B$4)) | L36: =IF(A36="","",IF(COUNTIFS(Pedidos!$C:$C,A36,Pedidos!$B:$B,"<="&EOMONTH(Parametros!$B$2,0))=0,"",_xlfn.MAXIFS(Pedidos!$B:$B,Pedidos!$C:$C,A36,Pedidos!$B:$B,"<="&EOMONTH(Parametros!$B$2,0)))) | M36: =IF(OR(L36="",F36=""),"",EDATE(L36,F36)) | N36: =IF(A36="","",IF(L36="","Sem histórico",IF(AND(L36>=Parametros!$B$2,L36<=EOMONTH(Parametros!$B$2,0)),"Comprou no mês",IF(M36="","Sem periodicidade",IF(M36<Parametros!$B$2,"Atrasado",IF(M36<=EOMONTH(Parametros!$B$2,0),"Previsto no mês","Em dia"))))))
I37: =IF(A37="","",COUNTIFS(Pedidos!$C:$C,A37,Pedidos!$K:$K,Parametros!$B$3)) | J37: =IF(A37="","",SUMIFS(Pedidos!$E:$E,Pedidos!$C:$C,A37,Pedidos!$K:$K,Parametros!$B$3)) | K37: =IF(A37="","",COUNTIFS(Pedidos!$C:$C,A37,Pedidos!$K:$K,Parametros!$B$4)) | L37: =IF(A37="","",IF(COUNTIFS(Pedidos!$C:$C,A37,Pedidos!$B:$B,"<="&EOMONTH(Parametros!$B$2,0))=0,"",_xlfn.MAXIFS(Pedidos!$B:$B,Pedidos!$C:$C,A37,Pedidos!$B:$B,"<="&EOMONTH(Parametros!$B$2,0)))) | M37: =IF(OR(L37="",F37=""),"",EDATE(L37,F37)) | N37: =IF(A37="","",IF(L37="","Sem histórico",IF(AND(L37>=Parametros!$B$2,L37<=EOMONTH(Parametros!$B$2,0)),"Comprou no mês",IF(M37="","Sem periodicidade",IF(M37<Parametros!$B$2,"Atrasado",IF(M37<=EOMONTH(Parametros!$B$2,0),"Previsto no mês","Em dia"))))))
I38: =IF(A38="","",COUNTIFS(Pedidos!$C:$C,A38,Pedidos!$K:$K,Parametros!$B$3)) | J38: =IF(A38="","",SUMIFS(Pedidos!$E:$E,Pedidos!$C:$C,A38,Pedidos!$K:$K,Parametros!$B$3)) | K38: =IF(A38="","",COUNTIFS(Pedidos!$C:$C,A38,Pedidos!$K:$K,Parametros!$B$4)) | L38: =IF(A38="","",IF(COUNTIFS(Pedidos!$C:$C,A38,Pedidos!$B:$B,"<="&EOMONTH(Parametros!$B$2,0))=0,"",_xlfn.MAXIFS(Pedidos!$B:$B,Pedidos!$C:$C,A38,Pedidos!$B:$B,"<="&EOMONTH(Parametros!$B$2,0)))) | M38: =IF(OR(L38="",F38=""),"",EDATE(L38,F38)) | N38: =IF(A38="","",IF(L38="","Sem histórico",IF(AND(L38>=Parametros!$B$2,L38<=EOMONTH(Parametros!$B$2,0)),"Comprou no mês",IF(M38="","Sem periodicidade",IF(M38<Parametros!$B$2,"Atrasado",IF(M38<=EOMONTH(Parametros!$B$2,0),"Previsto no mês","Em dia"))))))
I39: =IF(A39="","",COUNTIFS(Pedidos!$C:$C,A39,Pedidos!$K:$K,Parametros!$B$3)) | J39: =IF(A39="","",SUMIFS(Pedidos!$E:$E,Pedidos!$C:$C,A39,Pedidos!$K:$K,Parametros!$B$3)) | K39: =IF(A39="","",COUNTIFS(Pedidos!$C:$C,A39,Pedidos!$K:$K,Parametros!$B$4)) | L39: =IF(A39="","",IF(COUNTIFS(Pedidos!$C:$C,A39,Pedidos!$B:$B,"<="&EOMONTH(Parametros!$B$2,0))=0,"",_xlfn.MAXIFS(Pedidos!$B:$B,Pedidos!$C:$C,A39,Pedidos!$B:$B,"<="&EOMONTH(Parametros!$B$2,0)))) | M39: =IF(OR(L39="",F39=""),"",EDATE(L39,F39)) | N39: =IF(A39="","",IF(L39="","Sem histórico",IF(AND(L39>=Parametros!$B$2,L39<=EOMONTH(Parametros!$B$2,0)),"Comprou no mês",IF(M39="","Sem periodicidade",IF(M39<Parametros!$B$2,"Atrasado",IF(M39<=EOMONTH(Parametros!$B$2,0),"Previsto no mês","Em dia"))))))
... I501: =IF(A501="","",COUNTIFS(Pedidos!$C:$C,A501,Pedidos!$K:$K,Parametros!$B$3)) | J501: =IF(A501="","",SUMIFS(Pedidos!$E:$E,Pedidos!$C:$C,A501,Pedidos!$K:$K,Parametros!$B$3)) | K501: =IF(A501="","",COUNTIFS(Pedidos!$C:$C,A501,Pedidos!$K:$K,Parametros!$B$4)) | L501: =IF(A501="","",IF(COUNTIFS(Pedidos!$C:$C,A501,Pedidos!$B:$B,"<="&EOMONTH(Parametros!$B$2,0))=0,"",_xlfn.MAXIFS(Pedidos!$B:$B,Pedidos!$C:$C,A501,Pedidos!$B:$B,"<="&EOMONTH(Parametros!$B$2,0)))) | M501: =IF(OR(L501="",F501=""),"",EDATE(L501,F501)) | N501: =IF(A501="","",IF(L501="","Sem histórico",IF(AND(L501>=Parametros!$B$2,L501<=EOMONTH(Parametros!$B$2,0)),"Comprou no mês",IF(M501="","Sem periodicidade",IF(M501<Parametros!$B$2,"Atrasado",IF(M501<=EOMONTH(Parametros!$B$2,0),"Previsto no mês","Em dia"))))))

Sheet Pedidos
A1: Nº Pedido | B1: Data do pedido | C1: Cód. Cliente | D1: Produto | E1: Toneladas | F1: Valor (USD) | G1: Incoterm | H1: Embarque negociado | I1: Embarque realizado | J1: Cliente | K1: Ano | L1: Mês | M1: Dias até embarque | N1: Prazo de embarque
A2: PV1001 | B2: 45698 | C2: C001 | D2: Produto A 1kg | E2: 3.7 | F2: 33815.53 | G2: CFR | H2: 45728 | I2: 45730 | J2: =IF(C2="","",IFERROR(INDEX(Clientes!$B:$B,MATCH(C2,Clientes!$A:$A,0)),"Cód. não cadastrado")) | K2: =IF(B2="","",YEAR(B2)) | L2: =IF(B2="","",MONTH(B2)) | M2: =IF(OR(B2="",I2=""),"",I2-B2) | N2: =IF(B2="","",IF(I2="",IF(H2="","",IF(TODAY()>H2,"Atrasado (em aberto)","Em aberto")),IF(I2<=H2,"No prazo","Fora do prazo")))
A3: PV1002 | B3: 45752 | C3: C001 | D3: Produto B 5kg | E3: 3.2 | F3: 45069.71 | G3: CIF | H3: 45782 | I3: 45782 | J3: =IF(C3="","",IFERROR(INDEX(Clientes!$B:$B,MATCH(C3,Clientes!$A:$A,0)),"Cód. não cadastrado")) | K3: =IF(B3="","",YEAR(B3)) | L3: =IF(B3="","",MONTH(B3)) | M3: =IF(OR(B3="",I3=""),"",I3-B3) | N3: =IF(B3="","",IF(I3="",IF(H3="","",IF(TODAY()>H3,"Atrasado (em aberto)","Em aberto")),IF(I3<=H3,"No prazo","Fora do prazo")))
A4: PV1003 | B4: 45827 | C4: C001 | D4: Produto B 5kg | E4: 5 | F4: 30758.03 | G4: CFR | H4: 45857 | I4: 45866 | J4: =IF(C4="","",IFERROR(INDEX(Clientes!$B:$B,MATCH(C4,Clientes!$A:$A,0)),"Cód. não cadastrado")) | K4: =IF(B4="","",YEAR(B4)) | L4: =IF(B4="","",MONTH(B4)) | M4: =IF(OR(B4="",I4=""),"",I4-B4) | N4: =IF(B4="","",IF(I4="",IF(H4="","",IF(TODAY()>H4,"Atrasado (em aberto)","Em aberto")),IF(I4<=H4,"No prazo","Fora do prazo")))
A5: PV1004 | B5: 45888 | C5: C001 | D5: Produto B 5kg | E5: 3.4 | F5: 19211.82 | G5: CFR | H5: 45918 | I5: 45927 | J5: =IF(C5="","",IFERROR(INDEX(Clientes!$B:$B,MATCH(C5,Clientes!$A:$A,0)),"Cód. não cadastrado")) | K5: =IF(B5="","",YEAR(B5)) | L5: =IF(B5="","",MONTH(B5)) | M5: =IF(OR(B5="",I5=""),"",I5-B5) | N5: =IF(B5="","",IF(I5="",IF(H5="","",IF(TODAY()>H5,"Atrasado (em aberto)","Em aberto")),IF(I5<=H5,"No prazo","Fora do prazo")))
A6: PV1005 | B6: 45946 | C6: C001 | D6: Produto C granel 25kg | E6: 3.4 | F6: 47902.17 | G6: CFR | H6: 45976 | I6: 45981 | J6: =IF(C6="","",IFERROR(INDEX(Clientes!$B:$B,MATCH(C6,Clientes!$A:$A,0)),"Cód. não cadastrado")) | K6: =IF(B6="","",YEAR(B6)) | L6: =IF(B6="","",MONTH(B6)) | M6: =IF(OR(B6="",I6=""),"",I6-B6) | N6: =IF(B6="","",IF(I6="",IF(H6="","",IF(TODAY()>H6,"Atrasado (em aberto)","Em aberto")),IF(I6<=H6,"No prazo","Fora do prazo")))
A7: PV1006 | B7: 46012 | C7: C001 | D7: Produto C granel 25kg | E7: 7.9 | F7: 27806.8 | G7: CFR | H7: 46042 | I7: 46044 | J7: =IF(C7="","",IFERROR(INDEX(Clientes!$B:$B,MATCH(C7,Clientes!$A:$A,0)),"Cód. não cadastrado")) | K7: =IF(B7="","",YEAR(B7)) | L7: =IF(B7="","",MONTH(B7)) | M7: =IF(OR(B7="",I7=""),"",I7-B7) | N7: =IF(B7="","",IF(I7="",IF(H7="","",IF(TODAY()>H7,"Atrasado (em aberto)","Em aberto")),IF(I7<=H7,"No prazo","Fora do prazo")))
A8: PV1007 | B8: 46118 | C8: C001 | D8: Produto A 1kg | E8: 6 | F8: 24819.35 | G8: CFR | H8: 46148 | I8: 46150 | J8: =IF(C8="","",IFERROR(INDEX(Clientes!$B:$B,MATCH(C8,Clientes!$A:$A,0)),"Cód. não cadastrado")) | K8: =IF(B8="","",YEAR(B8)) | L8: =IF(B8="","",MONTH(B8)) | M8: =IF(OR(B8="",I8=""),"",I8-B8) | N8: =IF(B8="","",IF(I8="",IF(H8="","",IF(TODAY()>H8,"Atrasado (em aberto)","Em aberto")),IF(I8<=H8,"No prazo","Fora do prazo")))
A9: PV1008 | B9: 46247 | C9: C001 | D9: Produto B 5kg | E9: 3.5 | F9: 35213.43 | G9: CIF | H9: 46277 | I9: 46286 | J9: =IF(C9="","",IFERROR(INDEX(Clientes!$B:$B,MATCH(C9,Clientes!$A:$A,0)),"Cód. não cadastrado")) | K9: =IF(B9="","",YEAR(B9)) | L9: =IF(B9="","",MONTH(B9)) | M9: =IF(OR(B9="",I9=""),"",I9-B9) | N9: =IF(B9="","",IF(I9="",IF(H9="","",IF(TODAY()>H9,"Atrasado (em aberto)","Em aberto")),IF(I9<=H9,"No prazo","Fora do prazo")))
A10: PV1009 | B10: 45662 | C10: C002 | D10: Produto B 5kg | E10: 8.2 | F10: 27528.95 | G10: CFR | H10: 45692 | I10: 45701 | J10: =IF(C10="","",IFERROR(INDEX(Clientes!$B:$B,MATCH(C10,Clientes!$A:$A,0)),"Cód. não cadastrado")) | K10: =IF(B10="","",YEAR(B10)) | L10: =IF(B10="","",MONTH(B10)) | M10: =IF(OR(B10="",I10=""),"",I10-B10) | N10: =IF(B10="","",IF(I10="",IF(H10="","",IF(TODAY()>H10,"Atrasado (em aberto)","Em aberto")),IF(I10<=H10,"No prazo","Fora do prazo")))
A11: PV1010 | B11: 45700 | C11: C002 | D11: Produto B 5kg | E11: 8.7 | F11: 21791.44 | G11: FOB | H11: 45730 | I11: 45735 | J11: =IF(C11="","",IFERROR(INDEX(Clientes!$B:$B,MATCH(C11,Clientes!$A:$A,0)),"Cód. não cadastrado")) | K11: =IF(B11="","",YEAR(B11)) | L11: =IF(B11="","",MONTH(B11)) | M11: =IF(OR(B11="",I11=""),"",I11-B11) | N11: =IF(B11="","",IF(I11="",IF(H11="","",IF(TODAY()>H11,"Atrasado (em aberto)","Em aberto")),IF(I11<=H11,"No prazo","Fora do prazo")))
A12: PV1011 | B12: 45721 | C12: C002 | D12: Produto C granel 25kg | E12: 4.4 | F12: 36823.32 | G12: CIF | H12: 45751 | I12: 45748 | J12: =IF(C12="","",IFERROR(INDEX(Clientes!$B:$B,MATCH(C12,Clientes!$A:$A,0)),"Cód. não cadastrado")) | K12: =IF(B12="","",YEAR(B12)) | L12: =IF(B12="","",MONTH(B12)) | M12: =IF(OR(B12="",I12=""),"",I12-B12) | N12: =IF(B12="","",IF(I12="",IF(H12="","",IF(TODAY()>H12,"Atrasado (em aberto)","Em aberto")),IF(I12<=H12,"No prazo","Fora do prazo")))
A13: PV1012 | B13: 45753 | C13: C002 | D13: Produto B 5kg | E13: 3 | F13: 33852.59 | G13: CFR | H13: 45783 | I13: 45783 | J13: =IF(C13="","",IFERROR(INDEX(Clientes!$B:$B,MATCH(C13,Clientes!$A:$A,0)),"Cód. não cadastrado")) | K13: =IF(B13="","",YEAR(B13)) | L13: =IF(B13="","",MONTH(B13)) | M13: =IF(OR(B13="",I13=""),"",I13-B13) | N13: =IF(B13="","",IF(I13="",IF(H13="","",IF(TODAY()>H13,"Atrasado (em aberto)","Em aberto")),IF(I13<=H13,"No prazo","Fora do prazo")))
... A79: PV1078 | B79: 46237 | C79: C006 | D79: Produto C granel 25kg | E79: 8.1 | F79: 21986.35 | G79: CIF | H79: 46267 | I79: 46269 | J79: =IF(C79="","",IFERROR(INDEX(Clientes!$B:$B,MATCH(C79,Clientes!$A:$A,0)),"Cód. não cadastrado")) | K79: =IF(B79="","",YEAR(B79)) | L79: =IF(B79="","",MONTH(B79)) | M79: =IF(OR(B79="",I79=""),"",I79-B79) | N79: =IF(B79="","",IF(I79="",IF(H79="","",IF(TODAY()>H79,"Atrasado (em aberto)","Em aberto")),IF(I79<=H79,"No prazo","Fora do prazo")))
A80: PV1079 | B80: 46285 | C80: C006 | D80: Produto B 5kg | E80: 7.3 | F80: 37238.58 | G80: CFR | H80: 46315 | J80: =IF(C80="","",IFERROR(INDEX(Clientes!$B:$B,MATCH(C80,Clientes!$A:$A,0)),"Cód. não cadastrado")) | K80: =IF(B80="","",YEAR(B80)) | L80: =IF(B80="","",MONTH(B80)) | M80: =IF(OR(B80="",I80=""),"",I80-B80) | N80: =IF(B80="","",IF(I80="",IF(H80="","",IF(TODAY()>H80,"Atrasado (em aberto)","Em aberto")),IF(I80<=H80,"No prazo","Fora do prazo")))
A81: PV1080 | B81: 45736 | C81: C007 | D81: Produto A 1kg | E81: 3.3 | F81: 52588.03 | G81: CIF | H81: 45766 | I81: 45771 | J81: =IF(C81="","",IFERROR(INDEX(Clientes!$B:$B,MATCH(C81,Clientes!$A:$A,0)),"Cód. não cadastrado")) | K81: =IF(B81="","",YEAR(B81)) | L81: =IF(B81="","",MONTH(B81)) | M81: =IF(OR(B81="",I81=""),"",I81-B81) | N81: =IF(B81="","",IF(I81="",IF(H81="","",IF(TODAY()>H81,"Atrasado (em aberto)","Em aberto")),IF(I81<=H81,"No prazo","Fora do prazo")))
A82: PV1081 | B82: 45829 | C82: C007 | D82: Produto C granel 25kg | E82: 7.2 | F82: 37749.35 | G82: CIF | H82: 45859 | I82: 45859 | J82: =IF(C82="","",IFERROR(INDEX(Clientes!$B:$B,MATCH(C82,Clientes!$A:$A,0)),"Cód. não cadastrado")) | K82: =IF(B82="","",YEAR(B82)) | L82: =IF(B82="","",MONTH(B82)) | M82: =IF(OR(B82="",I82=""),"",I82-B82) | N82: =IF(B82="","",IF(I82="",IF(H82="","",IF(TODAY()>H82,"Atrasado (em aberto)","Em aberto")),IF(I82<=H82,"No prazo","Fora do prazo")))
A83: PV1082 | B83: 45925 | C83: C007 | D83: Produto C granel 25kg | E83: 8 | F83: 51210.49 | G83: CIF | H83: 45955 | I83: 45957 | J83: =IF(C83="","",IFERROR(INDEX(Clientes!$B:$B,MATCH(C83,Clientes!$A:$A,0)),"Cód. não cadastrado")) | K83: =IF(B83="","",YEAR(B83)) | L83: =IF(B83="","",MONTH(B83)) | M83: =IF(OR(B83="",I83=""),"",I83-B83) | N83: =IF(B83="","",IF(I83="",IF(H83="","",IF(TODAY()>H83,"Atrasado (em aberto)","Em aberto")),IF(I83<=H83,"No prazo","Fora do prazo")))
A84: PV1083 | B84: 46010 | C84: C007 | D84: Produto C granel 25kg | E84: 7.1 | F84: 46199.68 | G84: FOB | H84: 46040 | I84: 46049 | J84: =IF(C84="","",IFERROR(INDEX(Clientes!$B:$B,MATCH(C84,Clientes!$A:$A,0)),"Cód. não cadastrado")) | K84: =IF(B84="","",YEAR(B84)) | L84: =IF(B84="","",MONTH(B84)) | M84: =IF(OR(B84="",I84=""),"",I84-B84) | N84: =IF(B84="","",IF(I84="",IF(H84="","",IF(TODAY()>H84,"Atrasado (em aberto)","Em aberto")),IF(I84<=H84,"No prazo","Fora do prazo")))
A85: PV1084 | B85: 46207 | C85: C007 | D85: Produto B 5kg | E85: 6.4 | F85: 43249.52 | G85: CIF | H85: 46237 | I85: 46237 | J85: =IF(C85="","",IFERROR(INDEX(Clientes!$B:$B,MATCH(C85,Clientes!$A:$A,0)),"Cód. não cadastrado")) | K85: =IF(B85="","",YEAR(B85)) | L85: =IF(B85="","",MONTH(B85)) | M85: =IF(OR(B85="",I85=""),"",I85-B85) | N85: =IF(B85="","",IF(I85="",IF(H85="","",IF(TODAY()>H85,"Atrasado (em aberto)","Em aberto")),IF(I85<=H85,"No prazo","Fora do prazo")))
A86: PV1085 | B86: 45799 | C86: C008 | D86: Produto B 5kg | E86: 4.6 | F86: 35562.68 | G86: FOB | H86: 45829 | I86: 45826 | J86: =IF(C86="","",IFERROR(INDEX(Clientes!$B:$B,MATCH(C86,Clientes!$A:$A,0)),"Cód. não cadastrado")) | K86: =IF(B86="","",YEAR(B86)) | L86: =IF(B86="","",MONTH(B86)) | M86: =IF(OR(B86="",I86=""),"",I86-B86) | N86: =IF(B86="","",IF(I86="",IF(H86="","",IF(TODAY()>H86,"Atrasado (em aberto)","Em aberto")),IF(I86<=H86,"No prazo","Fora do prazo")))
A87: PV1086 | B87: 45985 | C87: C008 | D87: Produto C granel 25kg | E87: 3.6 | F87: 38669.56 | G87: CIF | H87: 46015 | I87: 46017 | J87: =IF(C87="","",IFERROR(INDEX(Clientes!$B:$B,MATCH(C87,Clientes!$A:$A,0)),"Cód. não cadastrado")) | K87: =IF(B87="","",YEAR(B87)) | L87: =IF(B87="","",MONTH(B87)) | M87: =IF(OR(B87="",I87=""),"",I87-B87) | N87: =IF(B87="","",IF(I87="",IF(H87="","",IF(TODAY()>H87,"Atrasado (em aberto)","Em aberto")),IF(I87<=H87,"No prazo","Fora do prazo")))
A88: PV1087 | B88: 46199 | C88: C008 | D88: Produto B 5kg | E88: 4.4 | F88: 49039.86 | G88: FOB | H88: 46229 | I88: 46223 | J88: =IF(C88="","",IFERROR(INDEX(Clientes!$B:$B,MATCH(C88,Clientes!$A:$A,0)),"Cód. não cadastrado")) | K88: =IF(B88="","",YEAR(B88)) | L88: =IF(B88="","",MONTH(B88)) | M88: =IF(OR(B88="",I88=""),"",I88-B88) | N88: =IF(B88="","",IF(I88="",IF(H88="","",IF(TODAY()>H88,"Atrasado (em aberto)","Em aberto")),IF(I88<=H88,"No prazo","Fora do prazo")))
A89: PV1088 | B89: 45704 | C89: C009 | D89: Produto B 5kg | E89: 3.5 | F89: 55971 | G89: CFR | H89: 45734 | I89: 45743 | J89: =IF(C89="","",IFERROR(INDEX(Clientes!$B:$B,MATCH(C89,Clientes!$A:$A,0)),"Cód. não cadastrado")) | K89: =IF(B89="","",YEAR(B89)) | L89: =IF(B89="","",MONTH(B89)) | M89: =IF(OR(B89="",I89=""),"",I89-B89) | N89: =IF(B89="","",IF(I89="",IF(H89="","",IF(TODAY()>H89,"Atrasado (em aberto)","Em aberto")),IF(I89<=H89,"No prazo","Fora do prazo")))
A90: PV1089 | B90: 45772 | C90: C009 | D90: Produto C granel 25kg | E90: 6.8 | F90: 23923.06 | G90: CIF | H90: 45802 | I90: 45796 | J90: =IF(C90="","",IFERROR(INDEX(Clientes!$B:$B,MATCH(C90,Clientes!$A:$A,0)),"Cód. não cadastrado")) | K90: =IF(B90="","",YEAR(B90)) | L90: =IF(B90="","",MONTH(B90)) | M90: =IF(OR(B90="",I90=""),"",I90-B90) | N90: =IF(B90="","",IF(I90="",IF(H90="","",IF(TODAY()>H90,"Atrasado (em aberto)","Em aberto")),IF(I90<=H90,"No prazo","Fora do prazo")))
A91: PV1090 | B91: 45813 | C91: C009 | D91: Produto B 5kg | E91: 6.9 | F91: 46179.91 | G91: CIF | H91: 45843 | I91: 45843 | J91: =IF(C91="","",IFERROR(INDEX(Clientes!$B:$B,MATCH(C91,Clientes!$A:$A,0)),"Cód. não cadastrado")) | K91: =IF(B91="","",YEAR(B91)) | L91: =IF(B91="","",MONTH(B91)) | M91: =IF(OR(B91="",I91=""),"",I91-B91) | N91: =IF(B91="","",IF(I91="",IF(H91="","",IF(TODAY()>H91,"Atrasado (em aberto)","Em aberto")),IF(I91<=H91,"No prazo","Fora do prazo")))
A92: PV1091 | B92: 45888 | C92: C009 | D92: Produto A 1kg | E92: 5.9 | F92: 36860.91 | G92: CIF | H92: 45918 | I92: 45915 | J92: =IF(C92="","",IFERROR(INDEX(Clientes!$B:$B,MATCH(C92,Clientes!$A:$A,0)),"Cód. não cadastrado")) | K92: =IF(B92="","",YEAR(B92)) | L92: =IF(B92="","",MONTH(B92)) | M92: =IF(OR(B92="",I92=""),"",I92-B92) | N92: =IF(B92="","",IF(I92="",IF(H92="","",IF(TODAY()>H92,"Atrasado (em aberto)","Em aberto")),IF(I92<=H92,"No prazo","Fora do prazo")))
... A96: PV1095 | B96: 46096 | C96: C009 | D96: Produto B 5kg | E96: 4.3 | F96: 57551.43 | G96: FOB | H96: 46126 | I96: 46126 | J96: =IF(C96="","",IFERROR(INDEX(Clientes!$B:$B,MATCH(C96,Clientes!$A:$A,0)),"Cód. não cadastrado")) | K96: =IF(B96="","",YEAR(B96)) | L96: =IF(B96="","",MONTH(B96)) | M96: =IF(OR(B96="",I96=""),"",I96-B96) | N96: =IF(B96="","",IF(I96="",IF(H96="","",IF(TODAY()>H96,"Atrasado (em aberto)","Em aberto")),IF(I96<=H96,"No prazo","Fora do prazo")))
A97: PV1096 | B97: 46274 | C97: C009 | D97: Produto A 1kg | E97: 6.6 | F97: 43425.07 | G97: CFR | H97: 46304 | J97: =IF(C97="","",IFERROR(INDEX(Clientes!$B:$B,MATCH(C97,Clientes!$A:$A,0)),"Cód. não cadastrado")) | K97: =IF(B97="","",YEAR(B97)) | L97: =IF(B97="","",MONTH(B97)) | M97: =IF(OR(B97="",I97=""),"",I97-B97) | N97: =IF(B97="","",IF(I97="",IF(H97="","",IF(TODAY()>H97,"Atrasado (em aberto)","Em aberto")),IF(I97<=H97,"No prazo","Fora do prazo")))
A98: PV1097 | B98: 45680 | C98: C010 | D98: Produto A 1kg | E98: 6 | F98: 54426.54 | G98: CFR | H98: 45710 | I98: 45710 | J98: =IF(C98="","",IFERROR(INDEX(Clientes!$B:$B,MATCH(C98,Clientes!$A:$A,0)),"Cód. não cadastrado")) | K98: =IF(B98="","",YEAR(B98)) | L98: =IF(B98="","",MONTH(B98)) | M98: =IF(OR(B98="",I98=""),"",I98-B98) | N98: =IF(B98="","",IF(I98="",IF(H98="","",IF(TODAY()>H98,"Atrasado (em aberto)","Em aberto")),IF(I98<=H98,"No prazo","Fora do prazo")))
A99: PV1098 | B99: 45689 | C99: C010 | D99: Produto A 1kg | E99: 8.7 | F99: 45671.47 | G99: CFR | H99: 45719 | I99: 45716 | J99: =IF(C99="","",IFERROR(INDEX(Clientes!$B:$B,MATCH(C99,Clientes!$A:$A,0)),"Cód. não cadastrado")) | K99: =IF(B99="","",YEAR(B99)) | L99: =IF(B99="","",MONTH(B99)) | M99: =IF(OR(B99="",I99=""),"",I99-B99) | N99: =IF(B99="","",IF(I99="",IF(H99="","",IF(TODAY()>H99,"Atrasado (em aberto)","Em aberto")),IF(I99<=H99,"No prazo","Fora do prazo")))
A100: PV1099 | B100: 45726 | C100: C010 | D100: Produto A 1kg | E100: 5.5 | F100: 31924.78 | G100: FOB | H100: 45756 | I100: 45761 | J100: =IF(C100="","",IFERROR(INDEX(Clientes!$B:$B,MATCH(C100,Clientes!$A:$A,0)),"Cód. não cadastrado")) | K100: =IF(B100="","",YEAR(B100)) | L100: =IF(B100="","",MONTH(B100)) | M100: =IF(OR(B100="",I100=""),"",I100-B100) | N100: =IF(B100="","",IF(I100="",IF(H100="","",IF(TODAY()>H100,"Atrasado (em aberto)","Em aberto")),IF(I100<=H100,"No prazo","Fora do prazo")))
A101: PV1100 | B101: 45758 | C101: C010 | D101: Produto B 5kg | E101: 7.5 | F101: 52759.99 | G101: FOB | H101: 45788 | I101: 45782 | J101: =IF(C101="","",IFERROR(INDEX(Clientes!$B:$B,MATCH(C101,Clientes!$A:$A,0)),"Cód. não cadastrado")) | K101: =IF(B101="","",YEAR(B101)) | L101: =IF(B101="","",MONTH(B101)) | M101: =IF(OR(B101="",I101=""),"",I101-B101) | N101: =IF(B101="","",IF(I101="",IF(H101="","",IF(TODAY()>H101,"Atrasado (em aberto)","Em aberto")),IF(I101<=H101,"No prazo","Fora do prazo")))
A102: PV1101 | B102: 45784 | C102: C010 | D102: Produto A 1kg | E102: 8.4 | F102: 28042.48 | G102: CFR | H102: 45814 | I102: 45819 | J102: =IF(C102="","",IFERROR(INDEX(Clientes!$B:$B,MATCH(C102,Clientes!$A:$A,0)),"Cód. não cadastrado")) | K102: =IF(B102="","",YEAR(B102)) | L102: =IF(B102="","",MONTH(B102)) | M102: =IF(OR(B102="",I102=""),"",I102-B102) | N102: =IF(B102="","",IF(I102="",IF(H102="","",IF(TODAY()>H102,"Atrasado (em aberto)","Em aberto")),IF(I102<=H102,"No prazo","Fora do prazo")))
A103: PV1102 | B103: 45811 | C103: C010 | D103: Produto B 5kg | E103: 9 | F103: 41512.95 | G103: CFR | H103: 45841 | I103: 45841 | J103: =IF(C103="","",IFERROR(INDEX(Clientes!$B:$B,MATCH(C103,Clientes!$A:$A,0)),"Cód. não cadastrado")) | K103: =IF(B103="","",YEAR(B103)) | L103: =IF(B103="","",MONTH(B103)) | M103: =IF(OR(B103="",I103=""),"",I103-B103) | N103: =IF(B103="","",IF(I103="",IF(H103="","",IF(TODAY()>H103,"Atrasado (em aberto)","Em aberto")),IF(I103<=H103,"No prazo","Fora do prazo")))
A104: PV1103 | B104: 45852 | C104: C010 | D104: Produto B 5kg | E104: 8.1 | F104: 27628.7 | G104: FOB | H104: 45882 | I104: 45891 | J104: =IF(C104="","",IFERROR(INDEX(Clientes!$B:$B,MATCH(C104,Clientes!$A:$A,0)),"Cód. não cadastrado")) | K104: =IF(B104="","",YEAR(B104)) | L104: =IF(B104="","",MONTH(B104)) | M104: =IF(OR(B104="",I104=""),"",I104-B104) | N104: =IF(B104="","",IF(I104="",IF(H104="","",IF(TODAY()>H104,"Atrasado (em aberto)","Em aberto")),IF(I104<=H104,"No prazo","Fora do prazo")))
A105: PV1104 | B105: 45891 | C105: C010 | D105: Produto C granel 25kg | E105: 8.6 | F105: 26219.61 | G105: CFR | H105: 45921 | I105: 45921 | J105: =IF(C105="","",IFERROR(INDEX(Clientes!$B:$B,MATCH(C105,Clientes!$A:$A,0)),"Cód. não cadastrado")) | K105: =IF(B105="","",YEAR(B105)) | L105: =IF(B105="","",MONTH(B105)) | M105: =IF(OR(B105="",I105=""),"",I105-B105) | N105: =IF(B105="","",IF(I105="",IF(H105="","",IF(TODAY()>H105,"Atrasado (em aberto)","Em aberto")),IF(I105<=H105,"No prazo","Fora do prazo")))
A106: PV1105 | B106: 45914 | C106: C010 | D106: Produto B 5kg | E106: 4.1 | F106: 31800.72 | G106: CFR | H106: 45944 | I106: 45946 | J106: =IF(C106="","",IFERROR(INDEX(Clientes!$B:$B,MATCH(C106,Clientes!$A:$A,0)),"Cód. não cadastrado")) | K106: =IF(B106="","",YEAR(B106)) | L106: =IF(B106="","",MONTH(B106)) | M106: =IF(OR(B106="",I106=""),"",I106-B106) | N106: =IF(B106="","",IF(I106="",IF(H106="","",IF(TODAY()>H106,"Atrasado (em aberto)","Em aberto")),IF(I106<=H106,"No prazo","Fora do prazo")))
A107: PV1106 | B107: 45931 | C107: C010 | D107: Produto C granel 25kg | E107: 5.4 | F107: 54407.69 | G107: CIF | H107: 45961 | I107: 45970 | J107: =IF(C107="","",IFERROR(INDEX(Clientes!$B:$B,MATCH(C107,Clientes!$A:$A,0)),"Cód. não cadastrado")) | K107: =IF(B107="","",YEAR(B107)) | L107: =IF(B107="","",MONTH(B107)) | M107: =IF(OR(B107="",I107=""),"",I107-B107) | N107: =IF(B107="","",IF(I107="",IF(H107="","",IF(TODAY()>H107,"Atrasado (em aberto)","Em aberto")),IF(I107<=H107,"No prazo","Fora do prazo")))
A108: PV1107 | B108: 45979 | C108: C010 | D108: Produto C granel 25kg | E108: 3.5 | F108: 57005.94 | G108: CFR | H108: 46009 | I108: 46006 | J108: =IF(C108="","",IFERROR(INDEX(Clientes!$B:$B,MATCH(C108,Clientes!$A:$A,0)),"Cód. não cadastrado")) | K108: =IF(B108="","",YEAR(B108)) | L108: =IF(B108="","",MONTH(B108)) | M108: =IF(OR(B108="",I108=""),"",I108-B108) | N108: =IF(B108="","",IF(I108="",IF(H108="","",IF(TODAY()>H108,"Atrasado (em aberto)","Em aberto")),IF(I108<=H108,"No prazo","Fora do prazo")))
...

Sheet Acompanhamento
A1: Mês ref. | B1: Cód. Cliente | C1: Cliente | D1: Compra prevista em | E1: Situação | F1: Motivo | G1: Detalhe do motivo | H1: Ação combinada | I1: Responsável | J1: Data de retorno | K1: Status da ação | L1: Chance de recompra

Sheet S_Atividades
A1: Nº Pedido | B1: Cliente | C1: Departamento | D1: Atividade | E1: Data solicitação | F1: Prazo (dias) | G1: Data conclusão | H1: Nº cobranças | I1: Última cobrança | J1: Causa do atraso | K1: Observação | L1: Data limite | M1: Status | N1: Dias de atraso
A2: PV1239 | B2: Cliente Exemplo 26 | C2: Marketing/Arte | D2: Arte de rótulo no idioma | E2: 46282 | G2: 46291 | H2: 1 | I2: 46289 | J2: Aguardando aprovação do cliente | L2: =IF(E2="","",E2+IF(F2="",IFERROR(VLOOKUP(C2,Parametros!$E:$F,2,0),0),F2)) | M2: =IF(E2="","",IF(G2="",IF(TODAY()>L2,"Atrasada","Em aberto"),IF(G2<=L2,"No prazo","Com atraso"))) | N2: =IF(E2="","",MAX(0,IF(G2="",TODAY(),G2)-L2))
A3: PV1239 | B3: Cliente Exemplo 26 | C3: PCP/Produção | D3: Programar produção | E3: 46283 | H3: 3 | I3: 46298 | J3: Fila da produção | L3: =IF(E3="","",E3+IF(F3="",IFERROR(VLOOKUP(C3,Parametros!$E:$F,2,0),0),F3)) | M3: =IF(E3="","",IF(G3="",IF(TODAY()>L3,"Atrasada","Em aberto"),IF(G3<=L3,"No prazo","Com atraso"))) | N3: =IF(E3="","",MAX(0,IF(G3="",TODAY(),G3)-L3))
A4: PV1239 | B4: Cliente Exemplo 26 | C4: Financeiro | D4: Liberação de crédito / carta de crédito | E4: 46281 | G4: 46284 | H4: 2 | I4: 46284 | L4: =IF(E4="","",E4+IF(F4="",IFERROR(VLOOKUP(C4,Parametros!$E:$F,2,0),0),F4)) | M4: =IF(E4="","",IF(G4="",IF(TODAY()>L4,"Atrasada","Em aberto"),IF(G4<=L4,"No prazo","Com atraso"))) | N4: =IF(E4="","",MAX(0,IF(G4="",TODAY(),G4)-L4))
A5: PV1239 | B5: Cliente Exemplo 26 | C5: Logística/Embarque | D5: Booking e coleta do contêiner | E5: 46282 | G5: 46289 | H5: 1 | I5: 46287 | J5: Aguardando aprovação do cliente | L5: =IF(E5="","",E5+IF(F5="",IFERROR(VLOOKUP(C5,Parametros!$E:$F,2,0),0),F5)) | M5: =IF(E5="","",IF(G5="",IF(TODAY()>L5,"Atrasada","Em aberto"),IF(G5<=L5,"No prazo","Com atraso"))) | N5: =IF(E5="","",MAX(0,IF(G5="",TODAY(),G5)-L5))
A6: PV1239 | B6: Cliente Exemplo 26 | C6: Comercial/Comex | D6: Proforma e confirmação | E6: 46282 | G6: 46284 | H6: 1 | I6: 46284 | L6: =IF(E6="","",E6+IF(F6="",IFERROR(VLOOKUP(C6,Parametros!$E:$F,2,0),0),F6)) | M6: =IF(E6="","",IF(G6="",IF(TODAY()>L6,"Atrasada","Em aberto"),IF(G6<=L6,"No prazo","Com atraso"))) | N6: =IF(E6="","",MAX(0,IF(G6="",TODAY(),G6)-L6))
A7: PV1238 | B7: Cliente Exemplo 25 | C7: Qualidade/Regulatório | D7: Certificado sanitário / análise | E7: 46283 | G7: 46289 | H7: 1 | I7: 46290 | L7: =IF(E7="","",E7+IF(F7="",IFERROR(VLOOKUP(C7,Parametros!$E:$F,2,0),0),F7)) | M7: =IF(E7="","",IF(G7="",IF(TODAY()>L7,"Atrasada","Em aberto"),IF(G7<=L7,"No prazo","Com atraso"))) | N7: =IF(E7="","",MAX(0,IF(G7="",TODAY(),G7)-L7))
A8: PV1238 | B8: Cliente Exemplo 25 | C8: Marketing/Arte | D8: Arte de rótulo no idioma | E8: 46284 | G8: 46290 | H8: 1 | I8: 46291 | L8: =IF(E8="","",E8+IF(F8="",IFERROR(VLOOKUP(C8,Parametros!$E:$F,2,0),0),F8)) | M8: =IF(E8="","",IF(G8="",IF(TODAY()>L8,"Atrasada","Em aberto"),IF(G8<=L8,"No prazo","Com atraso"))) | N8: =IF(E8="","",MAX(0,IF(G8="",TODAY(),G8)-L8))
A9: PV1238 | B9: Cliente Exemplo 25 | C9: Financeiro | D9: Liberação de crédito / carta de crédito | E9: 46284 | G9: 46286 | H9: 1 | I9: 46287 | L9: =IF(E9="","",E9+IF(F9="",IFERROR(VLOOKUP(C9,Parametros!$E:$F,2,0),0),F9)) | M9: =IF(E9="","",IF(G9="",IF(TODAY()>L9,"Atrasada","Em aberto"),IF(G9<=L9,"No prazo","Com atraso"))) | N9: =IF(E9="","",MAX(0,IF(G9="",TODAY(),G9)-L9))
A10: PV1238 | B10: Cliente Exemplo 25 | C10: PCP/Produção | D10: Programar produção | E10: 46282 | G10: 46296 | H10: 0 | L10: =IF(E10="","",E10+IF(F10="",IFERROR(VLOOKUP(C10,Parametros!$E:$F,2,0),0),F10)) | M10: =IF(E10="","",IF(G10="",IF(TODAY()>L10,"Atrasada","Em aberto"),IF(G10<=L10,"No prazo","Com atraso"))) | N10: =IF(E10="","",MAX(0,IF(G10="",TODAY(),G10)-L10))
A11: PV1238 | B11: Cliente Exemplo 25 | C11: Compras/Suprimentos | D11: Compra de embalagem/insumos | E11: 46283 | G11: 46293 | H11: 1 | I11: 46293 | L11: =IF(E11="","",E11+IF(F11="",IFERROR(VLOOKUP(C11,Parametros!$E:$F,2,0),0),F11)) | M11: =IF(E11="","",IF(G11="",IF(TODAY()>L11,"Atrasada","Em aberto"),IF(G11<=L11,"No prazo","Com atraso"))) | N11: =IF(E11="","",MAX(0,IF(G11="",TODAY(),G11)-L11))
A12: PV1237 | B12: Cliente Exemplo 24 | C12: PCP/Produção | D12: Programar produção | E12: 46271 | G12: 46283 | H12: 0 | L12: =IF(E12="","",E12+IF(F12="",IFERROR(VLOOKUP(C12,Parametros!$E:$F,2,0),0),F12)) | M12: =IF(E12="","",IF(G12="",IF(TODAY()>L12,"Atrasada","Em aberto"),IF(G12<=L12,"No prazo","Com atraso"))) | N12: =IF(E12="","",MAX(0,IF(G12="",TODAY(),G12)-L12))
A13: PV1237 | B13: Cliente Exemplo 24 | C13: Logística/Embarque | D13: Booking e coleta do contêiner | E13: 46272 | G13: 46276 | H13: 2 | I13: 46277 | L13: =IF(E13="","",E13+IF(F13="",IFERROR(VLOOKUP(C13,Parametros!$E:$F,2,0),0),F13)) | M13: =IF(E13="","",IF(G13="",IF(TODAY()>L13,"Atrasada","Em aberto"),IF(G13<=L13,"No prazo","Com atraso"))) | N13: =IF(E13="","",MAX(0,IF(G13="",TODAY(),G13)-L13))
A14: PV1237 | B14: Cliente Exemplo 24 | C14: Marketing/Arte | D14: Arte de rótulo no idioma | E14: 46273 | G14: 46277 | H14: 0 | L14: =IF(E14="","",E14+IF(F14="",IFERROR(VLOOKUP(C14,Parametros!$E:$F,2,0),0),F14)) | M14: =IF(E14="","",IF(G14="",IF(TODAY()>L14,"Atrasada","Em aberto"),IF(G14<=L14,"No prazo","Com atraso"))) | N14: =IF(E14="","",MAX(0,IF(G14="",TODAY(),G14)-L14))
A15: PV1237 | B15: Cliente Exemplo 24 | C15: Qualidade/Regulatório | D15: Certificado sanitário / análise | E15: 46273 | G15: 46288 | H15: 2 | I15: 46280 | J15: Aguardando aprovação do cliente | L15: =IF(E15="","",E15+IF(F15="",IFERROR(VLOOKUP(C15,Parametros!$E:$F,2,0),0),F15)) | M15: =IF(E15="","",IF(G15="",IF(TODAY()>L15,"Atrasada","Em aberto"),IF(G15<=L15,"No prazo","Com atraso"))) | N15: =IF(E15="","",MAX(0,IF(G15="",TODAY(),G15)-L15))
A16: PV1237 | B16: Cliente Exemplo 24 | C16: Financeiro | D16: Liberação de crédito / carta de crédito | E16: 46272 | G16: 46275 | H16: 0 | L16: =IF(E16="","",E16+IF(F16="",IFERROR(VLOOKUP(C16,Parametros!$E:$F,2,0),0),F16)) | M16: =IF(E16="","",IF(G16="",IF(TODAY()>L16,"Atrasada","Em aberto"),IF(G16<=L16,"No prazo","Com atraso"))) | N16: =IF(E16="","",MAX(0,IF(G16="",TODAY(),G16)-L16))
A17: PV1236 | B17: Cliente Exemplo 23 | C17: PCP/Produção | D17: Programar produção | E17: 46271 | G17: 46294 | H17: 2 | I17: 46286 | L17: =IF(E17="","",E17+IF(F17="",IFERROR(VLOOKUP(C17,Parametros!$E:$F,2,0),0),F17)) | M17: =IF(E17="","",IF(G17="",IF(TODAY()>L17,"Atrasada","Em aberto"),IF(G17<=L17,"No prazo","Com atraso"))) | N17: =IF(E17="","",MAX(0,IF(G17="",TODAY(),G17)-L17))
A18: PV1236 | B18: Cliente Exemplo 23 | C18: Documentação/Despachante | D18: Documentos de exportação | E18: 46271 | G18: 46280 | H18: 3 | I18: 46276 | J18: Aguardando aprovação do cliente | L18: =IF(E18="","",E18+IF(F18="",IFERROR(VLOOKUP(C18,Parametros!$E:$F,2,0),0),F18)) | M18: =IF(E18="","",IF(G18="",IF(TODAY()>L18,"Atrasada","Em aberto"),IF(G18<=L18,"No prazo","Com atraso"))) | N18: =IF(E18="","",MAX(0,IF(G18="",TODAY(),G18)-L18))
A19: PV1236 | B19: Cliente Exemplo 23 | C19: Logística/Embarque | D19: Booking e coleta do contêiner | E19: 46271 | G19: 46280 | H19: 0 | L19: =IF(E19="","",E19+IF(F19="",IFERROR(VLOOKUP(C19,Parametros!$E:$F,2,0),0),F19)) | M19: =IF(E19="","",IF(G19="",IF(TODAY()>L19,"Atrasada","Em aberto"),IF(G19<=L19,"No prazo","Com atraso"))) | N19: =IF(E19="","",MAX(0,IF(G19="",TODAY(),G19)-L19))
A20: PV1236 | B20: Cliente Exemplo 23 | C20: Qualidade/Regulatório | D20: Certificado sanitário / análise | E20: 46273 | G20: 46280 | H20: 1 | I20: 46280 | L20: =IF(E20="","",E20+IF(F20="",IFERROR(VLOOKUP(C20,Parametros!$E:$F,2,0),0),F20)) | M20: =IF(E20="","",IF(G20="",IF(TODAY()>L20,"Atrasada","Em aberto"),IF(G20<=L20,"No prazo","Com atraso"))) | N20: =IF(E20="","",MAX(0,IF(G20="",TODAY(),G20)-L20))
A21: PV1236 | B21: Cliente Exemplo 23 | C21: Comercial/Comex | D21: Proforma e confirmação | E21: 46270 | G21: 46272 | H21: 1 | I21: 46272 | L21: =IF(E21="","",E21+IF(F21="",IFERROR(VLOOKUP(C21,Parametros!$E:$F,2,0),0),F21)) | M21: =IF(E21="","",IF(G21="",IF(TODAY()>L21,"Atrasada","Em aberto"),IF(G21<=L21,"No prazo","Com atraso"))) | N21: =IF(E21="","",MAX(0,IF(G21="",TODAY(),G21)-L21))
A22: PV1235 | B22: Cliente Exemplo 23 | C22: Marketing/Arte | D22: Arte de rótulo no idioma | E22: 46278 | G22: 46287 | H22: 2 | I22: 46285 | J22: Aguardando aprovação do cliente | L22: =IF(E22="","",E22+IF(F22="",IFERROR(VLOOKUP(C22,Parametros!$E:$F,2,0),0),F22)) | M22: =IF(E22="","",IF(G22="",IF(TODAY()>L22,"Atrasada","Em aberto"),IF(G22<=L22,"No prazo","Com atraso"))) | N22: =IF(E22="","",MAX(0,IF(G22="",TODAY(),G22)-L22))
A23: PV1235 | B23: Cliente Exemplo 23 | C23: Documentação/Despachante | D23: Documentos de exportação | E23: 46280 | G23: 46293 | H23: 0 | L23: =IF(E23="","",E23+IF(F23="",IFERROR(VLOOKUP(C23,Parametros!$E:$F,2,0),0),F23)) | M23: =IF(E23="","",IF(G23="",IF(TODAY()>L23,"Atrasada","Em aberto"),IF(G23<=L23,"No prazo","Com atraso"))) | N23: =IF(E23="","",MAX(0,IF(G23="",TODAY(),G23)-L23))
A24: PV1235 | B24: Cliente Exemplo 23 | C24: Qualidade/Regulatório | D24: Certificado sanitário / análise | E24: 46281 | G24: 46285 | H24: 0 | L24: =IF(E24="","",E24+IF(F24="",IFERROR(VLOOKUP(C24,Parametros!$E:$F,2,0),0),F24)) | M24: =IF(E24="","",IF(G24="",IF(TODAY()>L24,"Atrasada","Em aberto"),IF(G24<=L24,"No prazo","Com atraso"))) | N24: =IF(E24="","",MAX(0,IF(G24="",TODAY(),G24)-L24))
A25: PV1235 | B25: Cliente Exemplo 23 | C25: Logística/Embarque | D25: Booking e coleta do contêiner | E25: 46280 | G25: 46287 | H25: 1 | I25: 46285 | J25: Aguardando aprovação do cliente | L25: =IF(E25="","",E25+IF(F25="",IFERROR(VLOOKUP(C25,Parametros!$E:$F,2,0),0),F25)) | M25: =IF(E25="","",IF(G25="",IF(TODAY()>L25,"Atrasada","Em aberto"),IF(G25<=L25,"No prazo","Com atraso"))) | N25: =IF(E25="","",MAX(0,IF(G25="",TODAY(),G25)-L25))
A26: PV1235 | B26: Cliente Exemplo 23 | C26: PCP/Produção | D26: Programar produção | E26: 46279 | G26: 46296 | H26: 1 | I26: 46294 | J26: Fornecedor atrasou | L26: =IF(E26="","",E26+IF(F26="",IFERROR(VLOOKUP(C26,Parametros!$E:$F,2,0),0),F26)) | M26: =IF(E26="","",IF(G26="",IF(TODAY()>L26,"Atrasada","Em aberto"),IF(G26<=L26,"No prazo","Com atraso"))) | N26: =IF(E26="","",MAX(0,IF(G26="",TODAY(),G26)-L26))
A27: PV1234 | B27: Cliente Exemplo 22 | C27: Documentação/Despachante | D27: Documentos de exportação | E27: 46286 | G27: 46293 | H27: 1 | I27: 46291 | L27: =IF(E27="","",E27+IF(F27="",IFERROR(VLOOKUP(C27,Parametros!$E:$F,2,0),0),F27)) | M27: =IF(E27="","",IF(G27="",IF(TODAY()>L27,"Atrasada","Em aberto"),IF(G27<=L27,"No prazo","Com atraso"))) | N27: =IF(E27="","",MAX(0,IF(G27="",TODAY(),G27)-L27))
A28: PV1234 | B28: Cliente Exemplo 22 | C28: PCP/Produção | D28: Programar produção | E28: 46287 | H28: 1 | I28: 46302 | L28: =IF(E28="","",E28+IF(F28="",IFERROR(VLOOKUP(C28,Parametros!$E:$F,2,0),0),F28)) | M28: =IF(E28="","",IF(G28="",IF(TODAY()>L28,"Atrasada","Em aberto"),IF(G28<=L28,"No prazo","Com atraso"))) | N28: =IF(E28="","",MAX(0,IF(G28="",TODAY(),G28)-L28))
A29: PV1234 | B29: Cliente Exemplo 22 | C29: Compras/Suprimentos | D29: Compra de embalagem/insumos | E29: 46287 | G29: 46299 | H29: 0 | J29: Fila da produção | L29: =IF(E29="","",E29+IF(F29="",IFERROR(VLOOKUP(C29,Parametros!$E:$F,2,0),0),F29)) | M29: =IF(E29="","",IF(G29="",IF(TODAY()>L29,"Atrasada","Em aberto"),IF(G29<=L29,"No prazo","Com atraso"))) | N29: =IF(E29="","",MAX(0,IF(G29="",TODAY(),G29)-L29))
A30: PV1234 | B30: Cliente Exemplo 22 | C30: Qualidade/Regulatório | D30: Certificado sanitário / análise | E30: 46284 | G30: 46291 | H30: 1 | I30: 46291 | L30: =IF(E30="","",E30+IF(F30="",IFERROR(VLOOKUP(C30,Parametros!$E:$F,2,0),0),F30)) | M30: =IF(E30="","",IF(G30="",IF(TODAY()>L30,"Atrasada","Em aberto"),IF(G30<=L30,"No prazo","Com atraso"))) | N30: =IF(E30="","",MAX(0,IF(G30="",TODAY(),G30)-L30))
A31: PV1234 | B31: Cliente Exemplo 22 | C31: Comercial/Comex | D31: Proforma e confirmação | E31: 46287 | G31: 46289 | H31: 0 | L31: =IF(E31="","",E31+IF(F31="",IFERROR(VLOOKUP(C31,Parametros!$E:$F,2,0),0),F31)) | M31: =IF(E31="","",IF(G31="",IF(TODAY()>L31,"Atrasada","Em aberto"),IF(G31<=L31,"No prazo","Com atraso"))) | N31: =IF(E31="","",MAX(0,IF(G31="",TODAY(),G31)-L31))
A32: PV1233 | B32: Cliente Exemplo 22 | C32: Compras/Suprimentos | D32: Compra de embalagem/insumos | E32: 46266 | G32: 46275 | H32: 1 | I32: 46276 | L32: =IF(E32="","",E32+IF(F32="",IFERROR(VLOOKUP(C32,Parametros!$E:$F,2,0),0),F32)) | M32: =IF(E32="","",IF(G32="",IF(TODAY()>L32,"Atrasada","Em aberto"),IF(G32<=L32,"No prazo","Com atraso"))) | N32: =IF(E32="","",MAX(0,IF(G32="",TODAY(),G32)-L32))
A33: PV1233 | B33: Cliente Exemplo 22 | C33: Qualidade/Regulatório | D33: Certificado sanitário / análise | E33: 46269 | G33: 46278 | H33: 1 | I33: 46276 | L33: =IF(E33="","",E33+IF(F33="",IFERROR(VLOOKUP(C33,Parametros!$E:$F,2,0),0),F33)) | M33: =IF(E33="","",IF(G33="",IF(TODAY()>L33,"Atrasada","Em aberto"),IF(G33<=L33,"No prazo","Com atraso"))) | N33: =IF(E33="","",MAX(0,IF(G33="",TODAY(),G33)-L33))
A34: PV1233 | B34: Cliente Exemplo 22 | C34: Financeiro | D34: Liberação de crédito / carta de crédito | E34: 46269 | G34: 46271 | H34: 1 | I34: 46272 | L34: =IF(E34="","",E34+IF(F34="",IFERROR(VLOOKUP(C34,Parametros!$E:$F,2,0),0),F34)) | M34: =IF(E34="","",IF(G34="",IF(TODAY()>L34,"Atrasada","Em aberto"),IF(G34<=L34,"No prazo","Com atraso"))) | N34: =IF(E34="","",MAX(0,IF(G34="",TODAY(),G34)-L34))
A35: PV1233 | B35: Cliente Exemplo 22 | C35: Marketing/Arte | D35: Arte de rótulo no idioma | E35: 46267 | G35: 46282 | H35: 0 | J35: Aguardando aprovação do cliente | L35: =IF(E35="","",E35+IF(F35="",IFERROR(VLOOKUP(C35,Parametros!$E:$F,2,0),0),F35)) | M35: =IF(E35="","",IF(G35="",IF(TODAY()>L35,"Atrasada","Em aberto"),IF(G35<=L35,"No prazo","Com atraso"))) | N35: =IF(E35="","",MAX(0,IF(G35="",TODAY(),G35)-L35))
A36: PV1233 | B36: Cliente Exemplo 22 | C36: PCP/Produção | D36: Programar produção | E36: 46269 | G36: 46288 | H36: 3 | I36: 46284 | J36: Aguardando aprovação do cliente | L36: =IF(E36="","",E36+IF(F36="",IFERROR(VLOOKUP(C36,Parametros!$E:$F,2,0),0),F36)) | M36: =IF(E36="","",IF(G36="",IF(TODAY()>L36,"Atrasada","Em aberto"),IF(G36<=L36,"No prazo","Com atraso"))) | N36: =IF(E36="","",MAX(0,IF(G36="",TODAY(),G36)-L36))
A37: PV1232 | B37: Cliente Exemplo 22 | C37: Logística/Embarque | D37: Booking e coleta do contêiner | E37: 46272 | G37: 46285 | H37: 3 | I37: 46277 | J37: Aguardando aprovação do cliente | L37: =IF(E37="","",E37+IF(F37="",IFERROR(VLOOKUP(C37,Parametros!$E:$F,2,0),0),F37)) | M37: =IF(E37="","",IF(G37="",IF(TODAY()>L37,"Atrasada","Em aberto"),IF(G37<=L37,"No prazo","Com atraso"))) | N37: =IF(E37="","",MAX(0,IF(G37="",TODAY(),G37)-L37))
A38: PV1232 | B38: Cliente Exemplo 22 | C38: Documentação/Despachante | D38: Documentos de exportação | E38: 46273 | G38: 46278 | H38: 1 | I38: 46278 | L38: =IF(E38="","",E38+IF(F38="",IFERROR(VLOOKUP(C38,Parametros!$E:$F,2,0),0),F38)) | M38: =IF(E38="","",IF(G38="",IF(TODAY()>L38,"Atrasada","Em aberto"),IF(G38<=L38,"No prazo","Com atraso"))) | N38: =IF(E38="","",MAX(0,IF(G38="",TODAY(),G38)-L38))
